[2023-06-13T06:19:49.104+0000] {taskinstance.py:1165} INFO - Dependencies all met for <TaskInstance: xcom_dag.task_4 manual__2023-06-13T06:19:43.286863+00:00 [queued]>
[2023-06-13T06:19:49.115+0000] {taskinstance.py:1165} INFO - Dependencies all met for <TaskInstance: xcom_dag.task_4 manual__2023-06-13T06:19:43.286863+00:00 [queued]>
[2023-06-13T06:19:49.116+0000] {taskinstance.py:1362} INFO - 
--------------------------------------------------------------------------------
[2023-06-13T06:19:49.117+0000] {taskinstance.py:1363} INFO - Starting attempt 1 of 1
[2023-06-13T06:19:49.119+0000] {taskinstance.py:1364} INFO - 
--------------------------------------------------------------------------------
[2023-06-13T06:19:49.131+0000] {taskinstance.py:1383} INFO - Executing <Task(PythonOperator): task_4> on 2023-06-13 06:19:43.286863+00:00
[2023-06-13T06:19:49.138+0000] {standard_task_runner.py:55} INFO - Started process 16412 to run task
[2023-06-13T06:19:49.142+0000] {standard_task_runner.py:82} INFO - Running: ['***', 'tasks', 'run', 'xcom_dag', 'task_4', 'manual__2023-06-13T06:19:43.286863+00:00', '--job-id', '92', '--raw', '--subdir', 'DAGS_FOLDER/xcom_dag.py', '--cfg-path', '/tmp/tmpqzkjbr99']
[2023-06-13T06:19:49.144+0000] {standard_task_runner.py:83} INFO - Job 92: Subtask task_4
[2023-06-13T06:19:49.222+0000] {task_command.py:376} INFO - Running <TaskInstance: xcom_dag.task_4 manual__2023-06-13T06:19:43.286863+00:00 [running]> on host c0d3dfdc775c
[2023-06-13T06:19:49.279+0000] {taskinstance.py:1592} INFO - Exporting the following env vars:
AIRFLOW_CTX_DAG_OWNER=***
AIRFLOW_CTX_DAG_ID=xcom_dag
AIRFLOW_CTX_TASK_ID=task_4
AIRFLOW_CTX_EXECUTION_DATE=2023-06-13T06:19:43.286863+00:00
AIRFLOW_CTX_TRY_NUMBER=1
AIRFLOW_CTX_DAG_RUN_ID=manual__2023-06-13T06:19:43.286863+00:00
[2023-06-13T06:19:49.282+0000] {logging_mixin.py:120} INFO - choose best model
[2023-06-13T06:19:49.311+0000] {taskinstance.py:1851} ERROR - Task failed with exception
Traceback (most recent call last):
  File "/home/airflow/.local/lib/python3.7/site-packages/airflow/operators/python.py", line 175, in execute
    return_value = self.execute_callable()
  File "/home/airflow/.local/lib/python3.7/site-packages/airflow/operators/python.py", line 193, in execute_callable
    return self.python_callable(*self.op_args, **self.op_kwargs)
  File "/opt/airflow/dags/xcom_dag.py", line 26, in _choose_best_model
    max_value = max(result, key=lambda x:result[x])
TypeError: '>' not supported between instances of 'NoneType' and 'NoneType'
[2023-06-13T06:19:49.326+0000] {taskinstance.py:1406} INFO - Marking task as FAILED. dag_id=xcom_dag, task_id=task_4, execution_date=20230613T061943, start_date=20230613T061949, end_date=20230613T061949
[2023-06-13T06:19:49.337+0000] {standard_task_runner.py:105} ERROR - Failed to execute job 92 for task task_4 ('>' not supported between instances of 'NoneType' and 'NoneType'; 16412)
[2023-06-13T06:19:49.360+0000] {local_task_job.py:164} INFO - Task exited with return code 1
[2023-06-13T06:19:49.379+0000] {local_task_job.py:273} INFO - 0 downstream tasks scheduled from follow-on schedule check
