[2023-06-13T06:18:45.133+0000] {taskinstance.py:1165} INFO - Dependencies all met for <TaskInstance: xcom_dag.task_4 scheduled__2023-06-12T00:00:00+00:00 [queued]>
[2023-06-13T06:18:45.141+0000] {taskinstance.py:1165} INFO - Dependencies all met for <TaskInstance: xcom_dag.task_4 scheduled__2023-06-12T00:00:00+00:00 [queued]>
[2023-06-13T06:18:45.143+0000] {taskinstance.py:1362} INFO - 
--------------------------------------------------------------------------------
[2023-06-13T06:18:45.144+0000] {taskinstance.py:1363} INFO - Starting attempt 1 of 1
[2023-06-13T06:18:45.145+0000] {taskinstance.py:1364} INFO - 
--------------------------------------------------------------------------------
[2023-06-13T06:18:45.155+0000] {taskinstance.py:1383} INFO - Executing <Task(PythonOperator): task_4> on 2023-06-12 00:00:00+00:00
[2023-06-13T06:18:45.161+0000] {standard_task_runner.py:55} INFO - Started process 16346 to run task
[2023-06-13T06:18:45.167+0000] {standard_task_runner.py:82} INFO - Running: ['***', 'tasks', 'run', 'xcom_dag', 'task_4', 'scheduled__2023-06-12T00:00:00+00:00', '--job-id', '87', '--raw', '--subdir', 'DAGS_FOLDER/xcom_dag.py', '--cfg-path', '/tmp/tmplw4o7zfk']
[2023-06-13T06:18:45.169+0000] {standard_task_runner.py:83} INFO - Job 87: Subtask task_4
[2023-06-13T06:18:45.246+0000] {task_command.py:376} INFO - Running <TaskInstance: xcom_dag.task_4 scheduled__2023-06-12T00:00:00+00:00 [running]> on host c0d3dfdc775c
[2023-06-13T06:18:45.297+0000] {taskinstance.py:1592} INFO - Exporting the following env vars:
AIRFLOW_CTX_DAG_OWNER=***
AIRFLOW_CTX_DAG_ID=xcom_dag
AIRFLOW_CTX_TASK_ID=task_4
AIRFLOW_CTX_EXECUTION_DATE=2023-06-12T00:00:00+00:00
AIRFLOW_CTX_TRY_NUMBER=1
AIRFLOW_CTX_DAG_RUN_ID=scheduled__2023-06-12T00:00:00+00:00
[2023-06-13T06:18:45.299+0000] {logging_mixin.py:120} INFO - choose best model
[2023-06-13T06:18:45.301+0000] {taskinstance.py:1851} ERROR - Task failed with exception
Traceback (most recent call last):
  File "/home/airflow/.local/lib/python3.7/site-packages/airflow/operators/python.py", line 175, in execute
    return_value = self.execute_callable()
  File "/home/airflow/.local/lib/python3.7/site-packages/airflow/operators/python.py", line 193, in execute_callable
    return self.python_callable(*self.op_args, **self.op_kwargs)
  File "/opt/airflow/dags/xcom_dag.py", line 21, in _choose_best_model
    accuracy_a = ti.xcom_pull(key = "accuracy", task_id = 'training_model_a')
  File "/home/airflow/.local/lib/python3.7/site-packages/airflow/utils/session.py", line 75, in wrapper
    return func(*args, session=session, **kwargs)
TypeError: xcom_pull() got an unexpected keyword argument 'task_id'
[2023-06-13T06:18:45.315+0000] {taskinstance.py:1406} INFO - Marking task as FAILED. dag_id=xcom_dag, task_id=task_4, execution_date=20230612T000000, start_date=20230613T061845, end_date=20230613T061845
[2023-06-13T06:18:45.324+0000] {standard_task_runner.py:105} ERROR - Failed to execute job 87 for task task_4 (xcom_pull() got an unexpected keyword argument 'task_id'; 16346)
[2023-06-13T06:18:45.340+0000] {local_task_job.py:164} INFO - Task exited with return code 1
[2023-06-13T06:18:45.358+0000] {local_task_job.py:273} INFO - 0 downstream tasks scheduled from follow-on schedule check
