[2023-06-14T00:14:08.082+0000] {taskinstance.py:1165} INFO - Dependencies all met for <TaskInstance: endToend_user_processing.extract_user scheduled__2023-06-13T00:00:00+00:00 [queued]>
[2023-06-14T00:14:08.092+0000] {taskinstance.py:1165} INFO - Dependencies all met for <TaskInstance: endToend_user_processing.extract_user scheduled__2023-06-13T00:00:00+00:00 [queued]>
[2023-06-14T00:14:08.094+0000] {taskinstance.py:1362} INFO - 
--------------------------------------------------------------------------------
[2023-06-14T00:14:08.095+0000] {taskinstance.py:1363} INFO - Starting attempt 1 of 1
[2023-06-14T00:14:08.096+0000] {taskinstance.py:1364} INFO - 
--------------------------------------------------------------------------------
[2023-06-14T00:14:08.106+0000] {taskinstance.py:1383} INFO - Executing <Task(SimpleHttpOperator): extract_user> on 2023-06-13 00:00:00+00:00
[2023-06-14T00:14:08.113+0000] {standard_task_runner.py:55} INFO - Started process 1150 to run task
[2023-06-14T00:14:08.119+0000] {standard_task_runner.py:82} INFO - Running: ['***', 'tasks', 'run', 'endToend_user_processing', 'extract_user', 'scheduled__2023-06-13T00:00:00+00:00', '--job-id', '157', '--raw', '--subdir', 'DAGS_FOLDER/user_processing.py', '--cfg-path', '/tmp/tmplndjme7_']
[2023-06-14T00:14:08.128+0000] {standard_task_runner.py:83} INFO - Job 157: Subtask extract_user
[2023-06-14T00:14:08.210+0000] {task_command.py:376} INFO - Running <TaskInstance: endToend_user_processing.extract_user scheduled__2023-06-13T00:00:00+00:00 [running]> on host 5f3b9c67a0bc
[2023-06-14T00:14:08.275+0000] {taskinstance.py:1592} INFO - Exporting the following env vars:
AIRFLOW_CTX_DAG_OWNER=***
AIRFLOW_CTX_DAG_ID=endToend_user_processing
AIRFLOW_CTX_TASK_ID=extract_user
AIRFLOW_CTX_EXECUTION_DATE=2023-06-13T00:00:00+00:00
AIRFLOW_CTX_TRY_NUMBER=1
AIRFLOW_CTX_DAG_RUN_ID=scheduled__2023-06-13T00:00:00+00:00
[2023-06-14T00:14:08.277+0000] {http.py:121} INFO - Calling HTTP method
[2023-06-14T00:14:08.290+0000] {base.py:71} INFO - Using connection ID 'user_api' for task execution.
[2023-06-14T00:14:08.294+0000] {http.py:148} INFO - Sending 'GET' to url: https://randomuser.me/api/
[2023-06-14T00:14:12.358+0000] {http.py:206} WARNING - ('Connection aborted.', RemoteDisconnected('Remote end closed connection without response')) Tenacity will retry to execute the operation
[2023-06-14T00:14:12.397+0000] {taskinstance.py:1851} ERROR - Task failed with exception
Traceback (most recent call last):
  File "/home/airflow/.local/lib/python3.7/site-packages/urllib3/connectionpool.py", line 710, in urlopen
    chunked=chunked,
  File "/home/airflow/.local/lib/python3.7/site-packages/urllib3/connectionpool.py", line 449, in _make_request
    six.raise_from(e, None)
  File "<string>", line 3, in raise_from
  File "/home/airflow/.local/lib/python3.7/site-packages/urllib3/connectionpool.py", line 444, in _make_request
    httplib_response = conn.getresponse()
  File "/usr/local/lib/python3.7/http/client.py", line 1373, in getresponse
    response.begin()
  File "/usr/local/lib/python3.7/http/client.py", line 319, in begin
    version, status, reason = self._read_status()
  File "/usr/local/lib/python3.7/http/client.py", line 288, in _read_status
    raise RemoteDisconnected("Remote end closed connection without"
http.client.RemoteDisconnected: Remote end closed connection without response

During handling of the above exception, another exception occurred:

Traceback (most recent call last):
  File "/home/airflow/.local/lib/python3.7/site-packages/requests/adapters.py", line 499, in send
    timeout=timeout,
  File "/home/airflow/.local/lib/python3.7/site-packages/urllib3/connectionpool.py", line 788, in urlopen
    method, url, error=e, _pool=self, _stacktrace=sys.exc_info()[2]
  File "/home/airflow/.local/lib/python3.7/site-packages/urllib3/util/retry.py", line 550, in increment
    raise six.reraise(type(error), error, _stacktrace)
  File "/home/airflow/.local/lib/python3.7/site-packages/urllib3/packages/six.py", line 769, in reraise
    raise value.with_traceback(tb)
  File "/home/airflow/.local/lib/python3.7/site-packages/urllib3/connectionpool.py", line 710, in urlopen
    chunked=chunked,
  File "/home/airflow/.local/lib/python3.7/site-packages/urllib3/connectionpool.py", line 449, in _make_request
    six.raise_from(e, None)
  File "<string>", line 3, in raise_from
  File "/home/airflow/.local/lib/python3.7/site-packages/urllib3/connectionpool.py", line 444, in _make_request
    httplib_response = conn.getresponse()
  File "/usr/local/lib/python3.7/http/client.py", line 1373, in getresponse
    response.begin()
  File "/usr/local/lib/python3.7/http/client.py", line 319, in begin
    version, status, reason = self._read_status()
  File "/usr/local/lib/python3.7/http/client.py", line 288, in _read_status
    raise RemoteDisconnected("Remote end closed connection without"
urllib3.exceptions.ProtocolError: ('Connection aborted.', RemoteDisconnected('Remote end closed connection without response'))

During handling of the above exception, another exception occurred:

Traceback (most recent call last):
  File "/home/airflow/.local/lib/python3.7/site-packages/airflow/providers/http/operators/http.py", line 123, in execute
    response = http.run(self.endpoint, self.data, self.headers, self.extra_options)
  File "/home/airflow/.local/lib/python3.7/site-packages/airflow/providers/http/hooks/http.py", line 149, in run
    return self.run_and_check(session, prepped_request, extra_options)
  File "/home/airflow/.local/lib/python3.7/site-packages/airflow/providers/http/hooks/http.py", line 207, in run_and_check
    raise ex
  File "/home/airflow/.local/lib/python3.7/site-packages/airflow/providers/http/hooks/http.py", line 199, in run_and_check
    response = session.send(prepped_request, **send_kwargs)
  File "/home/airflow/.local/lib/python3.7/site-packages/requests/sessions.py", line 701, in send
    r = adapter.send(request, **kwargs)
  File "/home/airflow/.local/lib/python3.7/site-packages/requests/adapters.py", line 547, in send
    raise ConnectionError(err, request=request)
requests.exceptions.ConnectionError: ('Connection aborted.', RemoteDisconnected('Remote end closed connection without response'))
[2023-06-14T00:14:12.578+0000] {taskinstance.py:1406} INFO - Marking task as FAILED. dag_id=endToend_user_processing, task_id=extract_user, execution_date=20230613T000000, start_date=20230614T001408, end_date=20230614T001412
[2023-06-14T00:14:12.793+0000] {standard_task_runner.py:105} ERROR - Failed to execute job 157 for task extract_user (('Connection aborted.', RemoteDisconnected('Remote end closed connection without response')); 1150)
[2023-06-14T00:14:13.096+0000] {local_task_job.py:164} INFO - Task exited with return code 1
[2023-06-14T00:14:13.195+0000] {local_task_job.py:273} INFO - 0 downstream tasks scheduled from follow-on schedule check
