[2023-06-07T18:15:26.560+0000] {taskinstance.py:1165} INFO - Dependencies all met for <TaskInstance: user_processing.store_user manual__2023-06-07T18:15:18.002479+00:00 [queued]>
[2023-06-07T18:15:26.569+0000] {taskinstance.py:1165} INFO - Dependencies all met for <TaskInstance: user_processing.store_user manual__2023-06-07T18:15:18.002479+00:00 [queued]>
[2023-06-07T18:15:26.571+0000] {taskinstance.py:1362} INFO - 
--------------------------------------------------------------------------------
[2023-06-07T18:15:26.572+0000] {taskinstance.py:1363} INFO - Starting attempt 1 of 1
[2023-06-07T18:15:26.573+0000] {taskinstance.py:1364} INFO - 
--------------------------------------------------------------------------------
[2023-06-07T18:15:26.583+0000] {taskinstance.py:1383} INFO - Executing <Task(PythonOperator): store_user> on 2023-06-07 18:15:18.002479+00:00
[2023-06-07T18:15:26.593+0000] {standard_task_runner.py:55} INFO - Started process 5013 to run task
[2023-06-07T18:15:26.598+0000] {standard_task_runner.py:82} INFO - Running: ['***', 'tasks', 'run', 'user_processing', 'store_user', 'manual__2023-06-07T18:15:18.002479+00:00', '--job-id', '14', '--raw', '--subdir', 'DAGS_FOLDER/user_processing.py', '--cfg-path', '/tmp/tmp6nhyozqp']
[2023-06-07T18:15:26.602+0000] {standard_task_runner.py:83} INFO - Job 14: Subtask store_user
[2023-06-07T18:15:26.674+0000] {task_command.py:376} INFO - Running <TaskInstance: user_processing.store_user manual__2023-06-07T18:15:18.002479+00:00 [running]> on host 2efdd707d2e6
[2023-06-07T18:15:26.736+0000] {taskinstance.py:1592} INFO - Exporting the following env vars:
AIRFLOW_CTX_DAG_OWNER=***
AIRFLOW_CTX_DAG_ID=user_processing
AIRFLOW_CTX_TASK_ID=store_user
AIRFLOW_CTX_EXECUTION_DATE=2023-06-07T18:15:18.002479+00:00
AIRFLOW_CTX_TRY_NUMBER=1
AIRFLOW_CTX_DAG_RUN_ID=manual__2023-06-07T18:15:18.002479+00:00
[2023-06-07T18:15:26.740+0000] {taskinstance.py:1851} ERROR - Task failed with exception
Traceback (most recent call last):
  File "/home/airflow/.local/lib/python3.7/site-packages/airflow/operators/python.py", line 175, in execute
    return_value = self.execute_callable()
  File "/home/airflow/.local/lib/python3.7/site-packages/airflow/operators/python.py", line 193, in execute_callable
    return self.python_callable(*self.op_args, **self.op_kwargs)
  File "/opt/airflow/dags/user_processing.py", line 28, in _store_user
    file_name = '/tmp/processed_user.csv'
TypeError: copy_expert() got an unexpected keyword argument 'file_name'
[2023-06-07T18:15:26.753+0000] {taskinstance.py:1406} INFO - Marking task as FAILED. dag_id=user_processing, task_id=store_user, execution_date=20230607T181518, start_date=20230607T181526, end_date=20230607T181526
[2023-06-07T18:15:26.763+0000] {standard_task_runner.py:105} ERROR - Failed to execute job 14 for task store_user (copy_expert() got an unexpected keyword argument 'file_name'; 5013)
[2023-06-07T18:15:26.814+0000] {local_task_job.py:164} INFO - Task exited with return code 1
[2023-06-07T18:15:26.842+0000] {local_task_job.py:273} INFO - 0 downstream tasks scheduled from follow-on schedule check
