[2023-06-13T06:59:03.323+0000] {taskinstance.py:1165} INFO - Dependencies all met for <TaskInstance: condition_trigger_dag.check_condition scheduled__2023-06-12T00:00:00+00:00 [queued]>
[2023-06-13T06:59:03.330+0000] {taskinstance.py:1165} INFO - Dependencies all met for <TaskInstance: condition_trigger_dag.check_condition scheduled__2023-06-12T00:00:00+00:00 [queued]>
[2023-06-13T06:59:03.331+0000] {taskinstance.py:1362} INFO - 
--------------------------------------------------------------------------------
[2023-06-13T06:59:03.333+0000] {taskinstance.py:1363} INFO - Starting attempt 1 of 1
[2023-06-13T06:59:03.334+0000] {taskinstance.py:1364} INFO - 
--------------------------------------------------------------------------------
[2023-06-13T06:59:03.348+0000] {taskinstance.py:1383} INFO - Executing <Task(BranchPythonOperator): check_condition> on 2023-06-12 00:00:00+00:00
[2023-06-13T06:59:03.355+0000] {standard_task_runner.py:55} INFO - Started process 18147 to run task
[2023-06-13T06:59:03.359+0000] {standard_task_runner.py:82} INFO - Running: ['***', 'tasks', 'run', 'condition_trigger_dag', 'check_condition', 'scheduled__2023-06-12T00:00:00+00:00', '--job-id', '121', '--raw', '--subdir', 'DAGS_FOLDER/condition_trigger_dag.py', '--cfg-path', '/tmp/tmpbln2sm9y']
[2023-06-13T06:59:03.361+0000] {standard_task_runner.py:83} INFO - Job 121: Subtask check_condition
[2023-06-13T06:59:03.422+0000] {task_command.py:376} INFO - Running <TaskInstance: condition_trigger_dag.check_condition scheduled__2023-06-12T00:00:00+00:00 [running]> on host c0d3dfdc775c
[2023-06-13T06:59:03.476+0000] {taskinstance.py:1592} INFO - Exporting the following env vars:
AIRFLOW_CTX_DAG_OWNER=***
AIRFLOW_CTX_DAG_ID=condition_trigger_dag
AIRFLOW_CTX_TASK_ID=check_condition
AIRFLOW_CTX_EXECUTION_DATE=2023-06-12T00:00:00+00:00
AIRFLOW_CTX_TRY_NUMBER=1
AIRFLOW_CTX_DAG_RUN_ID=scheduled__2023-06-12T00:00:00+00:00
[2023-06-13T06:59:03.478+0000] {taskinstance.py:1851} ERROR - Task failed with exception
Traceback (most recent call last):
  File "/home/airflow/.local/lib/python3.7/site-packages/airflow/operators/python.py", line 211, in execute
    branch = super().execute(context)
  File "/home/airflow/.local/lib/python3.7/site-packages/airflow/operators/python.py", line 175, in execute
    return_value = self.execute_callable()
  File "/home/airflow/.local/lib/python3.7/site-packages/airflow/operators/python.py", line 193, in execute_callable
    return self.python_callable(*self.op_args, **self.op_kwargs)
  File "/opt/airflow/dags/condition_trigger_dag.py", line 13, in _check_condition
    value = ti.xcom_pull("my_key", task_ids = "t1")
  File "/home/airflow/.local/lib/python3.7/site-packages/airflow/utils/session.py", line 75, in wrapper
    return func(*args, session=session, **kwargs)
TypeError: xcom_pull() got multiple values for argument 'task_ids'
[2023-06-13T06:59:03.490+0000] {taskinstance.py:1406} INFO - Marking task as FAILED. dag_id=condition_trigger_dag, task_id=check_condition, execution_date=20230612T000000, start_date=20230613T065903, end_date=20230613T065903
[2023-06-13T06:59:03.498+0000] {standard_task_runner.py:105} ERROR - Failed to execute job 121 for task check_condition (xcom_pull() got multiple values for argument 'task_ids'; 18147)
[2023-06-13T06:59:03.534+0000] {local_task_job.py:164} INFO - Task exited with return code 1
[2023-06-13T06:59:03.561+0000] {local_task_job.py:273} INFO - 0 downstream tasks scheduled from follow-on schedule check
